
Currently Loaded Modules:
  1) anaconda/2021-03-tf2

 

2021-07-27 15:12:41.679007: I tensorflow/stream_executor/platform/default/dso_loader.cc:49] Successfully opened dynamic library libcudart.so.10.1
Traceback (most recent call last):
  File "/home/moisioa3/.local/lib/python3.8/site-packages/transformers/tokenization_utils_base.py", line 215, in __getattr__
    return self.data[item]
KeyError: 'shuffle'

During handling of the above exception, another exception occurred:

Traceback (most recent call last):
  File "train.py", line 17, in <module>
    small_train_dataset = train_data.shuffle(seed=42).select(range(1000))
  File "/home/moisioa3/.local/lib/python3.8/site-packages/transformers/tokenization_utils_base.py", line 217, in __getattr__
    raise AttributeError
AttributeError
